WARNING 2020-01-29 01:54:53,750 base 21233 140531933378304 Method Not Allowed (POST): /articledetail/12/
WARNING 2020-01-29 01:54:53,751 log 21233 140531933378304 Method Not Allowed: /articledetail/12/
WARNING 2020-01-29 02:03:11,360 base 21233 140531890628352 Method Not Allowed (POST): /articledetail/12/
WARNING 2020-01-29 02:03:11,360 log 21233 140531890628352 Method Not Allowed: /articledetail/12/
WARNING 2020-01-29 02:08:56,147 log 21233 140531890628352 Not Found: /userprofile/userLogin/
WARNING 2020-01-29 02:13:56,809 log 21233 140531890628352 Not Found: /userprofile/userLogin/
WARNING 2020-01-29 02:13:58,263 log 21233 140531890628352 Not Found: /userprofile/userLogin/
WARNING 2020-01-29 02:15:48,044 log 21233 140531890628352 Not Found: /userprofile/userLogin/
WARNING 2020-01-29 02:17:47,839 log 27653 140232463054592 Not Found: /userprofile/userLogin/
WARNING 2020-01-29 02:33:38,147 log 27653 140232463054592 Not Found: /userprofile/userLogin/
WARNING 2020-01-29 02:43:32,599 log 28839 140438007076608 Not Found: /userprofile/userLogin/
ERROR 2020-01-29 02:43:40,996 log 28839 140438007076608 Internal Server Error: /comment/articlecomment/12
Traceback (most recent call last):
  File "/home/quantity123/python_work/3example_django/QttNewsWebsite/venv/lib/python3.7/site-packages/django/core/handlers/exception.py", line 34, in inner
    response = get_response(request)
  File "/home/quantity123/python_work/3example_django/QttNewsWebsite/venv/lib/python3.7/site-packages/django/core/handlers/base.py", line 115, in _get_response
    response = self.process_exception_by_middleware(e, request)
  File "/home/quantity123/python_work/3example_django/QttNewsWebsite/venv/lib/python3.7/site-packages/django/core/handlers/base.py", line 113, in _get_response
    response = wrapped_callback(request, *callback_args, **callback_kwargs)
TypeError: articleComment() got an unexpected keyword argument 'pk'
ERROR 2020-01-29 02:45:27,753 log 28839 140438007076608 Internal Server Error: /comment/articlecomment/12
Traceback (most recent call last):
  File "/home/quantity123/python_work/3example_django/QttNewsWebsite/venv/lib/python3.7/site-packages/django/core/handlers/exception.py", line 34, in inner
    response = get_response(request)
  File "/home/quantity123/python_work/3example_django/QttNewsWebsite/venv/lib/python3.7/site-packages/django/core/handlers/base.py", line 115, in _get_response
    response = self.process_exception_by_middleware(e, request)
  File "/home/quantity123/python_work/3example_django/QttNewsWebsite/venv/lib/python3.7/site-packages/django/core/handlers/base.py", line 113, in _get_response
    response = wrapped_callback(request, *callback_args, **callback_kwargs)
TypeError: articleComment() got an unexpected keyword argument 'pk'
ERROR 2020-01-29 02:46:51,163 log 28839 140438007076608 Internal Server Error: /comment/articlecomment/12
Traceback (most recent call last):
  File "/home/quantity123/python_work/3example_django/QttNewsWebsite/venv/lib/python3.7/site-packages/django/core/handlers/exception.py", line 34, in inner
    response = get_response(request)
  File "/home/quantity123/python_work/3example_django/QttNewsWebsite/venv/lib/python3.7/site-packages/django/core/handlers/base.py", line 115, in _get_response
    response = self.process_exception_by_middleware(e, request)
  File "/home/quantity123/python_work/3example_django/QttNewsWebsite/venv/lib/python3.7/site-packages/django/core/handlers/base.py", line 113, in _get_response
    response = wrapped_callback(request, *callback_args, **callback_kwargs)
TypeError: articleComment() got an unexpected keyword argument 'pk'
ERROR 2020-01-29 02:49:47,722 log 28839 140438007076608 Internal Server Error: /comment/articlecomment/12
Traceback (most recent call last):
  File "/home/quantity123/python_work/3example_django/QttNewsWebsite/venv/lib/python3.7/site-packages/django/core/handlers/exception.py", line 34, in inner
    response = get_response(request)
  File "/home/quantity123/python_work/3example_django/QttNewsWebsite/venv/lib/python3.7/site-packages/django/core/handlers/base.py", line 115, in _get_response
    response = self.process_exception_by_middleware(e, request)
  File "/home/quantity123/python_work/3example_django/QttNewsWebsite/venv/lib/python3.7/site-packages/django/core/handlers/base.py", line 113, in _get_response
    response = wrapped_callback(request, *callback_args, **callback_kwargs)
TypeError: articleComment() got an unexpected keyword argument 'pk'
ERROR 2020-01-29 02:56:36,452 log 28839 140438007076608 Internal Server Error: /comment/articlecomment/12
Traceback (most recent call last):
  File "/home/quantity123/python_work/3example_django/QttNewsWebsite/venv/lib/python3.7/site-packages/django/core/handlers/exception.py", line 34, in inner
    response = get_response(request)
  File "/home/quantity123/python_work/3example_django/QttNewsWebsite/venv/lib/python3.7/site-packages/django/core/handlers/base.py", line 115, in _get_response
    response = self.process_exception_by_middleware(e, request)
  File "/home/quantity123/python_work/3example_django/QttNewsWebsite/venv/lib/python3.7/site-packages/django/core/handlers/base.py", line 113, in _get_response
    response = wrapped_callback(request, *callback_args, **callback_kwargs)
TypeError: articleComment() got an unexpected keyword argument 'pk'
ERROR 2020-01-29 02:57:39,018 log 28839 140438007076608 Internal Server Error: /comment/articlecomment/12
Traceback (most recent call last):
  File "/home/quantity123/python_work/3example_django/QttNewsWebsite/venv/lib/python3.7/site-packages/django/core/handlers/exception.py", line 34, in inner
    response = get_response(request)
  File "/home/quantity123/python_work/3example_django/QttNewsWebsite/venv/lib/python3.7/site-packages/django/core/handlers/base.py", line 115, in _get_response
    response = self.process_exception_by_middleware(e, request)
  File "/home/quantity123/python_work/3example_django/QttNewsWebsite/venv/lib/python3.7/site-packages/django/core/handlers/base.py", line 113, in _get_response
    response = wrapped_callback(request, *callback_args, **callback_kwargs)
TypeError: articleComment() got an unexpected keyword argument 'pk'
ERROR 2020-01-29 02:57:40,182 log 28839 140438007076608 Internal Server Error: /comment/articlecomment/12
Traceback (most recent call last):
  File "/home/quantity123/python_work/3example_django/QttNewsWebsite/venv/lib/python3.7/site-packages/django/core/handlers/exception.py", line 34, in inner
    response = get_response(request)
  File "/home/quantity123/python_work/3example_django/QttNewsWebsite/venv/lib/python3.7/site-packages/django/core/handlers/base.py", line 115, in _get_response
    response = self.process_exception_by_middleware(e, request)
  File "/home/quantity123/python_work/3example_django/QttNewsWebsite/venv/lib/python3.7/site-packages/django/core/handlers/base.py", line 113, in _get_response
    response = wrapped_callback(request, *callback_args, **callback_kwargs)
TypeError: articleComment() got an unexpected keyword argument 'pk'
ERROR 2020-01-29 03:39:29,226 log 29555 140262040942336 Internal Server Error: /comment/articlecomment/12
Traceback (most recent call last):
  File "/home/quantity123/python_work/3example_django/QttNewsWebsite/venv/lib/python3.7/site-packages/django/core/handlers/exception.py", line 34, in inner
    response = get_response(request)
  File "/home/quantity123/python_work/3example_django/QttNewsWebsite/venv/lib/python3.7/site-packages/django/core/handlers/base.py", line 115, in _get_response
    response = self.process_exception_by_middleware(e, request)
  File "/home/quantity123/python_work/3example_django/QttNewsWebsite/venv/lib/python3.7/site-packages/django/core/handlers/base.py", line 113, in _get_response
    response = wrapped_callback(request, *callback_args, **callback_kwargs)
  File "/home/quantity123/python_work/3example_django/QttNewsWebsite/comment/views.py", line 15, in articleComment
    newComment.user = request.user
  File "/home/quantity123/python_work/3example_django/QttNewsWebsite/venv/lib/python3.7/site-packages/django/db/models/fields/related_descriptors.py", line 219, in __set__
    self.field.remote_field.model._meta.object_name,
ValueError: Cannot assign "<SimpleLazyObject: <django.contrib.auth.models.AnonymousUser object at 0x7f914d220e90>>": "Comment.user" must be a "User" instance.
ERROR 2020-01-29 15:29:22,884 log 5062 140371848546048 Internal Server Error: /comment/articlecomment/12
Traceback (most recent call last):
  File "/home/quantity123/python_work/3example_django/QttNewsWebsite/venv/lib/python3.7/site-packages/django/core/handlers/exception.py", line 34, in inner
    response = get_response(request)
  File "/home/quantity123/python_work/3example_django/QttNewsWebsite/venv/lib/python3.7/site-packages/django/core/handlers/base.py", line 115, in _get_response
    response = self.process_exception_by_middleware(e, request)
  File "/home/quantity123/python_work/3example_django/QttNewsWebsite/venv/lib/python3.7/site-packages/django/core/handlers/base.py", line 113, in _get_response
    response = wrapped_callback(request, *callback_args, **callback_kwargs)
  File "/home/quantity123/python_work/3example_django/QttNewsWebsite/comment/views.py", line 15, in articleComment
    newComment.user = request.user
  File "/home/quantity123/python_work/3example_django/QttNewsWebsite/venv/lib/python3.7/site-packages/django/db/models/fields/related_descriptors.py", line 219, in __set__
    self.field.remote_field.model._meta.object_name,
ValueError: Cannot assign "<SimpleLazyObject: <django.contrib.auth.models.AnonymousUser object at 0x7faadd1c0c50>>": "Comment.user" must be a "User" instance.
ERROR 2020-01-29 15:31:14,677 log 5062 140371848546048 Internal Server Error: /comment/articlecomment/12
Traceback (most recent call last):
  File "/home/quantity123/python_work/3example_django/QttNewsWebsite/venv/lib/python3.7/site-packages/django/core/handlers/exception.py", line 34, in inner
    response = get_response(request)
  File "/home/quantity123/python_work/3example_django/QttNewsWebsite/venv/lib/python3.7/site-packages/django/core/handlers/base.py", line 115, in _get_response
    response = self.process_exception_by_middleware(e, request)
  File "/home/quantity123/python_work/3example_django/QttNewsWebsite/venv/lib/python3.7/site-packages/django/core/handlers/base.py", line 113, in _get_response
    response = wrapped_callback(request, *callback_args, **callback_kwargs)
  File "/home/quantity123/python_work/3example_django/QttNewsWebsite/comment/views.py", line 15, in articleComment
    newComment.user = request.user
  File "/home/quantity123/python_work/3example_django/QttNewsWebsite/venv/lib/python3.7/site-packages/django/db/models/fields/related_descriptors.py", line 219, in __set__
    self.field.remote_field.model._meta.object_name,
ValueError: Cannot assign "<SimpleLazyObject: <django.contrib.auth.models.AnonymousUser object at 0x7faade337650>>": "Comment.user" must be a "User" instance.
ERROR 2020-01-29 15:31:34,940 log 5062 140371848546048 Internal Server Error: /comment/articlecomment/12
Traceback (most recent call last):
  File "/home/quantity123/python_work/3example_django/QttNewsWebsite/venv/lib/python3.7/site-packages/django/core/handlers/exception.py", line 34, in inner
    response = get_response(request)
  File "/home/quantity123/python_work/3example_django/QttNewsWebsite/venv/lib/python3.7/site-packages/django/core/handlers/base.py", line 115, in _get_response
    response = self.process_exception_by_middleware(e, request)
  File "/home/quantity123/python_work/3example_django/QttNewsWebsite/venv/lib/python3.7/site-packages/django/core/handlers/base.py", line 113, in _get_response
    response = wrapped_callback(request, *callback_args, **callback_kwargs)
  File "/home/quantity123/python_work/3example_django/QttNewsWebsite/comment/views.py", line 15, in articleComment
    newComment.user = request.user
  File "/home/quantity123/python_work/3example_django/QttNewsWebsite/venv/lib/python3.7/site-packages/django/db/models/fields/related_descriptors.py", line 219, in __set__
    self.field.remote_field.model._meta.object_name,
ValueError: Cannot assign "<SimpleLazyObject: <django.contrib.auth.models.AnonymousUser object at 0x7faade330a10>>": "Comment.user" must be a "User" instance.
ERROR 2020-01-29 15:31:37,521 log 5062 140371848546048 Internal Server Error: /comment/articlecomment/12
Traceback (most recent call last):
  File "/home/quantity123/python_work/3example_django/QttNewsWebsite/venv/lib/python3.7/site-packages/django/core/handlers/exception.py", line 34, in inner
    response = get_response(request)
  File "/home/quantity123/python_work/3example_django/QttNewsWebsite/venv/lib/python3.7/site-packages/django/core/handlers/base.py", line 115, in _get_response
    response = self.process_exception_by_middleware(e, request)
  File "/home/quantity123/python_work/3example_django/QttNewsWebsite/venv/lib/python3.7/site-packages/django/core/handlers/base.py", line 113, in _get_response
    response = wrapped_callback(request, *callback_args, **callback_kwargs)
  File "/home/quantity123/python_work/3example_django/QttNewsWebsite/comment/views.py", line 15, in articleComment
    newComment.user = request.user
  File "/home/quantity123/python_work/3example_django/QttNewsWebsite/venv/lib/python3.7/site-packages/django/db/models/fields/related_descriptors.py", line 219, in __set__
    self.field.remote_field.model._meta.object_name,
ValueError: Cannot assign "<SimpleLazyObject: <django.contrib.auth.models.AnonymousUser object at 0x7faadd1da1d0>>": "Comment.user" must be a "User" instance.
ERROR 2020-01-29 15:33:16,267 log 5664 140558526043904 Internal Server Error: /comment/articlecomment/12
Traceback (most recent call last):
  File "/home/quantity123/python_work/3example_django/QttNewsWebsite/venv/lib/python3.7/site-packages/django/core/handlers/exception.py", line 34, in inner
    response = get_response(request)
  File "/home/quantity123/python_work/3example_django/QttNewsWebsite/venv/lib/python3.7/site-packages/django/core/handlers/base.py", line 115, in _get_response
    response = self.process_exception_by_middleware(e, request)
  File "/home/quantity123/python_work/3example_django/QttNewsWebsite/venv/lib/python3.7/site-packages/django/core/handlers/base.py", line 113, in _get_response
    response = wrapped_callback(request, *callback_args, **callback_kwargs)
  File "/home/quantity123/python_work/3example_django/QttNewsWebsite/comment/views.py", line 15, in articleComment
    newComment.user = request.user
  File "/home/quantity123/python_work/3example_django/QttNewsWebsite/venv/lib/python3.7/site-packages/django/db/models/fields/related_descriptors.py", line 219, in __set__
    self.field.remote_field.model._meta.object_name,
ValueError: Cannot assign "<SimpleLazyObject: <django.contrib.auth.models.AnonymousUser object at 0x7fd6552339d0>>": "Comment.user" must be a "User" instance.
ERROR 2020-01-29 15:33:31,445 log 5678 140224948188928 Internal Server Error: /comment/articlecomment/12
Traceback (most recent call last):
  File "/home/quantity123/python_work/3example_django/QttNewsWebsite/venv/lib/python3.7/site-packages/django/core/handlers/exception.py", line 34, in inner
    response = get_response(request)
  File "/home/quantity123/python_work/3example_django/QttNewsWebsite/venv/lib/python3.7/site-packages/django/core/handlers/base.py", line 115, in _get_response
    response = self.process_exception_by_middleware(e, request)
  File "/home/quantity123/python_work/3example_django/QttNewsWebsite/venv/lib/python3.7/site-packages/django/core/handlers/base.py", line 113, in _get_response
    response = wrapped_callback(request, *callback_args, **callback_kwargs)
  File "/home/quantity123/python_work/3example_django/QttNewsWebsite/comment/views.py", line 15, in articleComment
    newComment.user = request.user
  File "/home/quantity123/python_work/3example_django/QttNewsWebsite/venv/lib/python3.7/site-packages/django/db/models/fields/related_descriptors.py", line 219, in __set__
    self.field.remote_field.model._meta.object_name,
ValueError: Cannot assign "<SimpleLazyObject: <django.contrib.auth.models.AnonymousUser object at 0x7f88aa41e190>>": "Comment.user" must be a "User" instance.
WARNING 2020-01-29 15:50:29,441 log 6569 139822977427200 Not Found: /userprofile/userLogin/
WARNING 2020-01-29 15:50:47,118 log 6593 140451767269120 Not Found: /userprofile/userLogin/
WARNING 2020-01-29 15:50:48,125 log 6593 140451767269120 Not Found: /userprofile/userLogin/
ERROR 2020-01-29 17:06:46,932 log 7116 140377709340416 Internal Server Error: /userprofile/userlogin/
Traceback (most recent call last):
  File "/home/quantity123/python_work/3example_django/QttNewsWebsite/venv/lib/python3.7/site-packages/django/core/handlers/exception.py", line 34, in inner
    response = get_response(request)
  File "/home/quantity123/python_work/3example_django/QttNewsWebsite/venv/lib/python3.7/site-packages/django/core/handlers/base.py", line 115, in _get_response
    response = self.process_exception_by_middleware(e, request)
  File "/home/quantity123/python_work/3example_django/QttNewsWebsite/venv/lib/python3.7/site-packages/django/core/handlers/base.py", line 113, in _get_response
    response = wrapped_callback(request, *callback_args, **callback_kwargs)
  File "/home/quantity123/python_work/3example_django/QttNewsWebsite/userprofile/views.py", line 17, in userLogin
    return redirect('article:homeView')
  File "/home/quantity123/python_work/3example_django/QttNewsWebsite/venv/lib/python3.7/site-packages/django/shortcuts.py", line 41, in redirect
    return redirect_class(resolve_url(to, *args, **kwargs))
  File "/home/quantity123/python_work/3example_django/QttNewsWebsite/venv/lib/python3.7/site-packages/django/shortcuts.py", line 131, in resolve_url
    return reverse(to, args=args, kwargs=kwargs)
  File "/home/quantity123/python_work/3example_django/QttNewsWebsite/venv/lib/python3.7/site-packages/django/urls/base.py", line 87, in reverse
    return iri_to_uri(resolver._reverse_with_prefix(view, prefix, *args, **kwargs))
  File "/home/quantity123/python_work/3example_django/QttNewsWebsite/venv/lib/python3.7/site-packages/django/urls/resolvers.py", line 677, in _reverse_with_prefix
    raise NoReverseMatch(msg)
django.urls.exceptions.NoReverseMatch: Reverse for 'homeView' not found. 'homeView' is not a valid view function or pattern name.
ERROR 2020-01-29 17:16:35,644 log 18263 140411047712512 Internal Server Error: /articledetail/12/
Traceback (most recent call last):
  File "/home/quantity123/python_work/3example_django/QttNewsWebsite/venv/lib/python3.7/site-packages/django/template/base.py", line 469, in parse
    compile_func = self.tags[command]
KeyError: 'forloop.counter'

During handling of the above exception, another exception occurred:

Traceback (most recent call last):
  File "/home/quantity123/python_work/3example_django/QttNewsWebsite/venv/lib/python3.7/site-packages/django/core/handlers/exception.py", line 34, in inner
    response = get_response(request)
  File "/home/quantity123/python_work/3example_django/QttNewsWebsite/venv/lib/python3.7/site-packages/django/core/handlers/base.py", line 145, in _get_response
    response = self.process_exception_by_middleware(e, request)
  File "/home/quantity123/python_work/3example_django/QttNewsWebsite/venv/lib/python3.7/site-packages/django/core/handlers/base.py", line 143, in _get_response
    response = response.render()
  File "/home/quantity123/python_work/3example_django/QttNewsWebsite/venv/lib/python3.7/site-packages/django/template/response.py", line 105, in render
    self.content = self.rendered_content
  File "/home/quantity123/python_work/3example_django/QttNewsWebsite/venv/lib/python3.7/site-packages/django/template/response.py", line 81, in rendered_content
    template = self.resolve_template(self.template_name)
  File "/home/quantity123/python_work/3example_django/QttNewsWebsite/venv/lib/python3.7/site-packages/django/template/response.py", line 63, in resolve_template
    return select_template(template, using=self.using)
  File "/home/quantity123/python_work/3example_django/QttNewsWebsite/venv/lib/python3.7/site-packages/django/template/loader.py", line 42, in select_template
    return engine.get_template(template_name)
  File "/home/quantity123/python_work/3example_django/QttNewsWebsite/venv/lib/python3.7/site-packages/django/template/backends/django.py", line 34, in get_template
    return Template(self.engine.get_template(template_name), self)
  File "/home/quantity123/python_work/3example_django/QttNewsWebsite/venv/lib/python3.7/site-packages/django/template/engine.py", line 143, in get_template
    template, origin = self.find_template(template_name)
  File "/home/quantity123/python_work/3example_django/QttNewsWebsite/venv/lib/python3.7/site-packages/django/template/engine.py", line 125, in find_template
    template = loader.get_template(name, skip=skip)
  File "/home/quantity123/python_work/3example_django/QttNewsWebsite/venv/lib/python3.7/site-packages/django/template/loaders/base.py", line 30, in get_template
    contents, origin, origin.template_name, self.engine,
  File "/home/quantity123/python_work/3example_django/QttNewsWebsite/venv/lib/python3.7/site-packages/django/template/base.py", line 156, in __init__
    self.nodelist = self.compile_nodelist()
  File "/home/quantity123/python_work/3example_django/QttNewsWebsite/venv/lib/python3.7/site-packages/django/template/base.py", line 194, in compile_nodelist
    return parser.parse()
  File "/home/quantity123/python_work/3example_django/QttNewsWebsite/venv/lib/python3.7/site-packages/django/template/base.py", line 477, in parse
    raise self.error(token, e)
  File "/home/quantity123/python_work/3example_django/QttNewsWebsite/venv/lib/python3.7/site-packages/django/template/base.py", line 475, in parse
    compiled_result = compile_func(self, token)
  File "/home/quantity123/python_work/3example_django/QttNewsWebsite/venv/lib/python3.7/site-packages/django/template/loader_tags.py", line 266, in do_extends
    nodelist = parser.parse()
  File "/home/quantity123/python_work/3example_django/QttNewsWebsite/venv/lib/python3.7/site-packages/django/template/base.py", line 477, in parse
    raise self.error(token, e)
  File "/home/quantity123/python_work/3example_django/QttNewsWebsite/venv/lib/python3.7/site-packages/django/template/base.py", line 475, in parse
    compiled_result = compile_func(self, token)
  File "/home/quantity123/python_work/3example_django/QttNewsWebsite/venv/lib/python3.7/site-packages/django/template/loader_tags.py", line 209, in do_block
    nodelist = parser.parse(('endblock',))
  File "/home/quantity123/python_work/3example_django/QttNewsWebsite/venv/lib/python3.7/site-packages/django/template/base.py", line 477, in parse
    raise self.error(token, e)
  File "/home/quantity123/python_work/3example_django/QttNewsWebsite/venv/lib/python3.7/site-packages/django/template/base.py", line 475, in parse
    compiled_result = compile_func(self, token)
  File "/home/quantity123/python_work/3example_django/QttNewsWebsite/venv/lib/python3.7/site-packages/django/template/defaulttags.py", line 811, in do_for
    nodelist_loop = parser.parse(('empty', 'endfor',))
  File "/home/quantity123/python_work/3example_django/QttNewsWebsite/venv/lib/python3.7/site-packages/django/template/base.py", line 471, in parse
    self.invalid_block_tag(token, command, parse_until)
  File "/home/quantity123/python_work/3example_django/QttNewsWebsite/venv/lib/python3.7/site-packages/django/template/base.py", line 527, in invalid_block_tag
    get_text_list(["'%s'" % p for p in parse_until], 'or'),
django.template.exceptions.TemplateSyntaxError: Invalid block tag on line 72: 'forloop.counter', expected 'empty' or 'endfor'. Did you forget to register or load this tag?
WARNING 2020-01-29 17:44:58,098 log 18263 140411057153792 Not Found: /Search
WARNING 2020-01-29 18:27:19,223 log 22087 140050253113088 Not Found: /Search
ERROR 2020-01-29 18:27:22,434 log 22087 140050253113088 Internal Server Error: /
Traceback (most recent call last):
  File "/home/quantity123/python_work/3example_django/QttNewsWebsite/venv/lib/python3.7/site-packages/django/core/handlers/exception.py", line 34, in inner
    response = get_response(request)
  File "/home/quantity123/python_work/3example_django/QttNewsWebsite/venv/lib/python3.7/site-packages/django/core/handlers/base.py", line 115, in _get_response
    response = self.process_exception_by_middleware(e, request)
  File "/home/quantity123/python_work/3example_django/QttNewsWebsite/venv/lib/python3.7/site-packages/django/core/handlers/base.py", line 113, in _get_response
    response = wrapped_callback(request, *callback_args, **callback_kwargs)
  File "/home/quantity123/python_work/3example_django/QttNewsWebsite/venv/lib/python3.7/site-packages/django/views/generic/base.py", line 71, in view
    return self.dispatch(request, *args, **kwargs)
  File "/home/quantity123/python_work/3example_django/QttNewsWebsite/venv/lib/python3.7/site-packages/django/views/generic/base.py", line 97, in dispatch
    return handler(request, *args, **kwargs)
  File "/home/quantity123/python_work/3example_django/QttNewsWebsite/venv/lib/python3.7/site-packages/django/views/generic/list.py", line 157, in get
    context = self.get_context_data()
  File "/home/quantity123/python_work/3example_django/QttNewsWebsite/article/views.py", line 36, in get_context_data
    context = super(Home, self).get_context_data(**kwargs)
  File "/home/quantity123/python_work/3example_django/QttNewsWebsite/article/views.py", line 29, in get_context_data
    context = super(CommonList, self).get_context_data(**kwargs)
  File "/home/quantity123/python_work/3example_django/QttNewsWebsite/venv/lib/python3.7/site-packages/django/views/generic/list.py", line 119, in get_context_data
    paginator, page, queryset, is_paginated = self.paginate_queryset(queryset, page_size)
  File "/home/quantity123/python_work/3example_django/QttNewsWebsite/venv/lib/python3.7/site-packages/django/views/generic/list.py", line 69, in paginate_queryset
    page = paginator.page(page_number)
  File "/home/quantity123/python_work/3example_django/QttNewsWebsite/venv/lib/python3.7/site-packages/django/core/paginator.py", line 70, in page
    number = self.validate_number(number)
  File "/home/quantity123/python_work/3example_django/QttNewsWebsite/venv/lib/python3.7/site-packages/django/core/paginator.py", line 48, in validate_number
    if number > self.num_pages:
  File "/home/quantity123/python_work/3example_django/QttNewsWebsite/venv/lib/python3.7/site-packages/django/utils/functional.py", line 48, in __get__
    res = instance.__dict__[self.name] = self.func(instance)
  File "/home/quantity123/python_work/3example_django/QttNewsWebsite/venv/lib/python3.7/site-packages/django/core/paginator.py", line 97, in num_pages
    if self.count == 0 and not self.allow_empty_first_page:
  File "/home/quantity123/python_work/3example_django/QttNewsWebsite/venv/lib/python3.7/site-packages/django/utils/functional.py", line 48, in __get__
    res = instance.__dict__[self.name] = self.func(instance)
  File "/home/quantity123/python_work/3example_django/QttNewsWebsite/venv/lib/python3.7/site-packages/django/core/paginator.py", line 92, in count
    return len(self.object_list)
TypeError: object of type 'NoneType' has no len()
